<mujoco model="reacher">
    <compiler angle="radian" inertiafromgeom="true"/>
    <default>
        <joint armature="1" damping="1" limited="true"/>
        <geom contype="1" friction="1 0.1 0.1" rgba="0.7 0.7 0 1"/>
    </default>
    <option gravity="0 0 -9.81" integrator="RK4" timestep="0.01"/>
    <asset>
        <texture type="skybox" builtin="gradient" rgb1="0.9 0.7 0.9" rgb2="0.94 0.97 0.97" width="2" height="2"/>
    </asset>
    <worldbody>
        <include file="lighting.xml"/>
        <include file="bordered-arena.xml"/>
        <!-- Object -->
        <body name="object" pos="0 0 0.01">
            <geom rgba="0 0.5 1 1" type="box" size="0.06 0.06 0.06" density='0.00001' contype="1"/>
            <joint name="particle_x" type="slide" pos="0 0 0" axis="1 0 0" range="-0.3 0.3" damping="0.1"/>
            <joint name="particle_y" type="slide" pos="0 0 0" axis="0 1 0" range="-0.3 0.3" damping="0.1"/>
        </body>
        <body name="distractor_1" pos="0 0.05 0.01">
            <geom rgba="0 1 0 1" type="box" size="0.06 0.06 0.06" density='0.00001' contype="0" conaffinity="0"/>
            <joint name="distractor_1_x" type="slide" pos="0 0 0" axis="1 0 0" range="-0.3 0.3" damping="0.1"/>
            <joint name="distractor_1_y" type="slide" pos="0 0 0" axis="0 1 0" range="-0.3 0.3" damping="0.1"/>
        </body>
        <body name="distractor_2" pos="0 0 0.01">
            <geom rgba="1 0.5 0 1" type="box" size="0.06 0.06 0.06" density='0.00001' contype="0" conaffinity="0"/>
            <joint name="distractor_2_x" type="slide" pos="0 0 0" axis="1 0 0" range="-0.3 0.3" damping="0.1"/>
            <joint name="distractor_2_y" type="slide" pos="0 0 0" axis="0 1 0" range="-0.3 0.3" damping="0.1"/>
        </body>
        <body name="distractor_3" pos="0.05 0 0.01">
            <geom rgba="0 0 0 1" type="box" size="0.06 0.06 0.06" density='0.00001' contype="0" conaffinity="0"/>
            <joint name="distractor_3_x" type="slide" pos="0 0 0" axis="1 0 0" range="-0.3 0.3" damping="0.1"/>
            <joint name="distractor_3_y" type="slide" pos="0 0 0" axis="0 1 0" range="-0.3 0.3" damping="0.1"/>
        </body>
        <!-- Goal -->
        <body name="goal" pos="0 0 0.01">
            <geom rgba="1 0.2 0.2 0.5" type="sphere" size="0.1" density='0.00001' contype="0" conaffinity="0"/>
            <joint name="goal_x" type="slide" pos="0 0 0" axis="1 0 0" range="-0.3 0.3" damping="0.5"/>
            <joint name="goal_y" type="slide" pos="0 0 0" axis="0 1 0" range="-0.3 0.3" damping="0.5"/>
        </body>
    </worldbody>
    <actuator>
        <motor ctrllimited="true" ctrlrange="-1.0 1.0" gear="10.0" joint="particle_x"/>
        <motor ctrllimited="true" ctrlrange="-1.0 1.0" gear="10.0" joint="particle_y"/>
        <motor ctrllimited="true" ctrlrange="-0.1 0.1" gear="10.0" joint="distractor_1_x"/>
        <motor ctrllimited="true" ctrlrange="-0.1 0.1" gear="10.0" joint="distractor_1_y"/>
        <motor ctrllimited="true" ctrlrange="-0.1 0.1" gear="10.0" joint="distractor_2_x"/>
        <motor ctrllimited="true" ctrlrange="-0.1 0.1" gear="10.0" joint="distractor_2_y"/>
        <motor ctrllimited="true" ctrlrange="-0.1 0.1" gear="10.0" joint="distractor_3_x"/>
        <motor ctrllimited="true" ctrlrange="-0.1 0.1" gear="10.0" joint="distractor_3_y"/>
    </actuator>
</mujoco>
