<?xml version="1.0" encoding="utf-8"?>
<mujoco>
    <geom conaffinity="0" contype="0" fromto="0 0 0 0 0 0.02" name="root" rgba="0.45 0.45 0.45 1" size=".0085"
          type="cylinder"/>
    <body name="body0" pos="0 0 .01">
        <geom name="link0" type="box" pos="0.055 0 0" size="0.05 0.005 0.005" rgba="0.75 0.75 0.75 1"/>
        <joint axis="0 0 1" limited="false" name="joint0" pos="0 0 0" type="hinge"/>
        <body name="body1" pos="0.1 0 0">
            <geom conaffinity="0" contype="0" fromto="0 0 -0.0075 0 0 0.0075" name="elbow" rgba="0.45 0.45 0.45 1" size=".008"
                  type="cylinder"/>
            <geom name="link1" type="box" pos="0.055 0 0" size="0.05 0.005 0.005" rgba="0.75 0.75 0.75 1"/>
            <joint axis="0 0 1" limited="true" name="joint1" pos="0 0 0" range="-3.0 3.0" type="hinge"/>
            <body name="fingertip" pos="0.11 0 0">
                <geom contype="0" name="fingertip" pos="0 0 0" rgba="0.9 0.3 0.3 1" size=".01" type="sphere"/>
            </body>
        </body>
    </body>
</mujoco>
