<mujoco model="pendulum">
    <compiler angle="radian" inertiafromgeom="true"/>
    <default>
        <joint armature="1" damping="1" limited="true"/>
        <geom contype="0" friction="1 0.1 0.1" rgba="0.7 0.7 0 1"/>
    </default>
    <option gravity="0 0 -9.81" integrator="RK4" timestep="0.01"/>
    <asset>
        <texture type="skybox" builtin="gradient" rgb1="0.9 0.7 0.9" rgb2="0.94 0.97 0.97" width="2" height="2"/>
    </asset>
    <worldbody>
        <!-- Arena -->
        <include file="pendulum-lighting.xml"/>
        <!--<geom conaffinity="0" contype="0" name="wall" pos="0 0.04 0" rgba="0.85 0.85 0.91 1" size="0.3 0.02 0.3"-->
              <!--type="box"/>-->
        <!-- Arm -->
        <geom conaffinity="0" contype="0" fromto="0 -0.01 0 0 0.01 0" name="root" rgba="0.45 0.45 0.45 1" size=".0085"
              type="cylinder"/>
        <body name="arm" pos="0 0 0">
            <geom name="link1" type="box" pos="0.055 0 0" size="0.05 0.005 0.005" rgba="0.75 0.75 0.75 1"/>
            <joint axis="0 1 0" limited="false" name="joint0" pos="0 0 0" type="hinge" damping="0"/>
            <body name="fingertip" pos="0.11 0 0">
                <geom contype="0" name="fingertip" pos="0 0 0" rgba="0.9 0.3 0.3 1" size=".01" mass="1000" type="sphere"/>
            </body>
        </body>
    </worldbody>
    <actuator>
        <motor forcelimited="true" forcerange="-1.0 1.0" gear="200.0" joint="joint0"/>
    </actuator>
</mujoco>
