<mujoco model="reacher">
    <compiler angle="radian" inertiafromgeom="true"/>
    <default>
        <joint armature="1" damping="1" limited="true"/>
        <geom contype="1" friction="1 0.1 0.1" rgba="0.7 0.7 0 1"/>
    </default>
    <option gravity="0 0 -9.81" integrator="RK4" timestep="0.01"/>
    <asset>
        <texture type="skybox" builtin="gradient" rgb1="0.9 0.7 0.9" rgb2="0.94 0.97 0.97" width="2" height="2"/>
    </asset>
    <worldbody>
        <include file="lighting.xml"/>
        <include file="bordered-arena.xml"/>
        <!-- Arm -->
        <body name="object" pos="0 0 0.01">
            <geom rgba="0 0.5 1 1" type="box" size="0.015 0.015 0.015" density='0.00001' contype="1"/>
            <joint name="particle_x" type="slide" pos="0 0 0" axis="1 0 0" range="-0.3 0.3" damping="0.1"/>
            <joint name="particle_y" type="slide" pos="0 0 0" axis="0 1 0" range="-0.3 0.3" damping="0.1"/>
        </body>
        <!-- Goal -->
        <body name="goal_0" pos="0.15 0.15 0.01">
            <geom rgba="1 0.3 0.3 0.2" type="cylinder" size="0.12 0.008" density='0.00001' contype="0" conaffinity="0"/>
        </body>
        <body name="goal_1" pos="0.15 -0.15 0.01">
            <geom rgba="0.9 0.6 0.3 0.2" type="cylinder" size="0.12 0.008" density='0.00001' contype="0" conaffinity="0"/>
        </body>
        <body name="goal_2" pos="-0.15 -0.15 0.01">
            <geom rgba="0.1 0.8 0.1 0.2" type="cylinder" size="0.12 0.008" density='0.00001' contype="0" conaffinity="0"/>
        </body>
        <body name="goal_3" pos="-0.15 0.15 0.01">
            <geom rgba="0.2 0.2 0.2 0.2" type="cylinder" size="0.12 0.008" density='0.00001' contype="0" conaffinity="0"/>
        </body>
    </worldbody>
    <actuator>
        <motor ctrllimited="true" ctrlrange="-1.0 1.0" gear="10.0" joint="particle_x"/>
        <motor ctrllimited="true" ctrlrange="-1.0 1.0" gear="10.0" joint="particle_y"/>
    </actuator>
</mujoco>
