<mujoco model="reacher">
    <compiler angle="radian" inertiafromgeom="true"/>
    <default>
        <joint armature="1" damping="1" limited="true"/>
        <geom contype="0" friction="1 0.1 0.1" rgba="0.7 0.7 0 1"/>
    </default>
    <option gravity="0 0 -9.81" integrator="RK4" timestep="0.01"/>
    <asset>
        <texture type="skybox" builtin="gradient" rgb1="0.9 0.7 0.9" rgb2="0.94 0.97 0.97" width="2" height="2"/>
    </asset>
    <worldbody>
        <!-- Arena -->
        <include file="lighting.xml"/>
        <geom conaffinity="0" contype="0" name="ground" pos="0 0 -0.02" rgba="0.85 0.85 0.91 1" size="0.3 0.3 0.02"
              type="box"/>
        <!-- Arm -->
        <include file="2-link-arm.xml"/>
        <!-- Target -->
        <body name="target" pos=".1 -.1 .01">
            <joint armature="0" axis="1 0 0" damping="0" limited="true" name="target_x" pos="0 0 0" range="-.27 .27"
                   ref=".1" stiffness="0" type="slide"/>
            <joint armature="0" axis="0 1 0" damping="0" limited="true" name="target_y" pos="0 0 0" range="-.27 .27"
                   ref="-.1" stiffness="0" type="slide"/>
            <geom name="target" type="box" pos="0 0 0" size="0.015 0.015 0.015" rgba="0 0.5 1 0.8" contype="0"
                  conaffinity="0"/>
        </body>
        <body name="distractor_1" pos=".1 .1 .01">
            <joint armature="0" axis="1 0 0" damping="0" limited="true" name="distractor_1_x" pos="0 0 0"
                   range="-.27 .27" ref=".1" stiffness="0" type="slide"/>
            <joint armature="0" axis="0 1 0" damping="0" limited="true" name="distractor_1_y" pos="0 0 0"
                   range="-.27 .27" ref=".1" stiffness="0" type="slide"/>
            <geom name="distractor_1" type="box" pos="0 0 0" size="0.015 0.015 0.015" rgba="1 0.5 0.5 0.8" contype="0"
                  conaffinity="0"/>
        </body>
    </worldbody>
    <actuator>
        <motor ctrllimited="true" ctrlrange="-1.0 1.0" gear="200.0" joint="joint0"/>
        <motor ctrllimited="true" ctrlrange="-1.0 1.0" gear="200.0" joint="joint1"/>
    </actuator>
</mujoco>
